#VRML_SIM V8.4.0 utf8
WorldInfo {
  basicTimeStep 16
}
Viewpoint {
  orientation -0.0485449 0.964874 0.258189 0.254386
  position 0.118745 0.0247426 0.351032
}
Background {
  skyColor [
    0.4 0.7 1
  ]
}
DirectionalLight {
  ambientIntensity 1
  direction -0.33 -1 -0.5
  castShadows TRUE
}
Floor {
  size 1 1
}
DEF WALL_1 Solid {
  translation 0.5 0.05 0
  children [
    DEF WALL_SHAPE Shape {
      appearance Appearance {
        material Material {
          diffuseColor 0.12549 0.368627 0.729412
        }
      }
      geometry Box {
        size 0.02 0.1 0.98
      }
    }
  ]
  boundingObject USE WALL_SHAPE
}
DEF WALL_2 Solid {
  translation -0.5 0.05 0
  children [
    USE WALL_SHAPE
  ]
  boundingObject USE WALL_SHAPE
}
DEF WALL_3 Solid {
  translation 0 0.05 -0.5
  rotation 0 1 0 1.5708
  children [
    USE WALL_SHAPE
  ]
  boundingObject USE WALL_SHAPE
}
DEF WALL_4 Solid {
  translation 0 0.05 0.5
  rotation 0 1 0 1.5708
  children [
    USE WALL_SHAPE
  ]
  boundingObject USE WALL_SHAPE
}
Robot {
  children [
    Transform {
      translation 0 0.07 0
      children [
        Transform {
          translation 0 -0.03 0
          rotation 0 0 1 1.5708
          children [
            HingeJoint {
              device [
                RotationalMotor {
                  name "back wheel motor"
                }
              ]
              endPoint Solid {
                translation 0 0 -0.04
                rotation 1 0 0 1.5708
                children [
                  Shape {
                    appearance Appearance {
                      material Material {
                      }
                    }
                    geometry Cylinder {
                      height 0.01
                      radius 0.03
                    }
                  }
                ]
                name "LEFT_WHEEL"
              }
            }
            HingeJoint {
              device [
                RotationalMotor {
                  name "left wheel motor"
                }
              ]
              endPoint Solid {
                translation 0 -0.03 0.02
                rotation 1 0 0 -0.5236
                children [
                  Shape {
                    appearance Appearance {
                      material Material {
                      }
                    }
                    geometry Cylinder {
                      height 0.01
                      radius 0.03
                    }
                  }
                ]
                name "LEFT_WHEEL"
              }
            }
            HingeJoint {
              device [
                RotationalMotor {
                  name "right wheel motor"
                }
              ]
              endPoint Solid {
                translation 0 0.03 0.02
                rotation 1 0 0 0.5236
                children [
                  Shape {
                    appearance Appearance {
                      material Material {
                      }
                    }
                    geometry Cylinder {
                      height 0.01
                      radius 0.03
                    }
                  }
                ]
                name "LEFT_WHEEL"
              }
            }
          ]
        }
        Camera {
          translation 0 0 0.05
          children [
            Shape {
              geometry Box {
                size 0.01 0.01 0.01
              }
            }
          ]
        }
        DEF BODY Shape {
          appearance Appearance {
            material Material {
              diffuseColor 1 0.5 0.5
              emissiveColor 0.5 0 0
            }
          }
          geometry Box {
            size 0.1 0.1 0.1
          }
        }
      ]
    }
  ]
  name "EyeBot"
}
