#VRML_SIM V8.4.0 utf8
WorldInfo {
  basicTimeStep 16
}
Viewpoint {
  orientation -0.430258 0.858209 0.279921 1.01436
  position 0.402459 0.357858 0.341741
}
Background {
  skyColor [
    0.4 0.7 1
  ]
}
DirectionalLight {
  ambientIntensity 1
  direction -0.33 -1 -0.5
  castShadows TRUE
}
Floor {
  size 1 1
}
DEF WALL_1 Solid {
  translation 0.5 0.05 0
  children [
    DEF WALL_SHAPE Shape {
      appearance Appearance {
        material Material {
          diffuseColor 0.12549 0.368627 0.729412
        }
      }
      geometry Box {
        size 0.02 0.1 0.98
      }
    }
  ]
  boundingObject USE WALL_SHAPE
}
DEF WALL_2 Solid {
  translation -0.5 0.05 0
  children [
    USE WALL_SHAPE
  ]
  boundingObject USE WALL_SHAPE
}
DEF WALL_3 Solid {
  translation 0 0.05 -0.5
  rotation 0 1 0 1.5708
  children [
    USE WALL_SHAPE
  ]
  boundingObject USE WALL_SHAPE
}
DEF WALL_4 Solid {
  translation 0 0.05 0.5
  rotation 0 1 0 1.5708
  children [
    USE WALL_SHAPE
  ]
  boundingObject USE WALL_SHAPE
}
Robot {
  children [
    Transform {
      translation 0 0.07 0
      children [
        DEF RIGHT_CONN Connector {
          translation -0.05 0 0
          name "right connector"
          isLocked TRUE
          autoLock TRUE
        }
        DEF LEFT_CONN Connector {
          translation 0.05 0 0
          name "left connector"
          isLocked TRUE
          autoLock TRUE
        }
        DEF BACK_CONN Connector {
          translation 0 0 -0.05
          name "back connector"
          isLocked TRUE
          autoLock TRUE
        }
        DEF FRONT_CONN Connector {
          translation 0 0 0.05
          name "front connector"
          isLocked TRUE
          autoLock TRUE
        }
        DEF RIGHT_SONAR DistanceSensor {
          translation -0.05 0 0
          rotation 0 1 0 3.14159
          children [
            Shape {
              geometry Box {
                size 0.01 0.01 0.01
              }
            }
          ]
          name "right distance sensor"
          lookupTable [
            0 0 0
            1 1000 0
          ]
          type "sonar"
          numberOfRays 2
        }
        DEF LEFT_SONAR DistanceSensor {
          translation 0.05 0 0
          children [
            Shape {
              geometry Box {
                size 0.01 0.01 0.01
              }
            }
          ]
          name "left distance sensor"
          lookupTable [
            0 0 0
            1 1000 0
          ]
          type "sonar"
          numberOfRays 2
        }
        DEF WHEEL_TRANSFORM Transform {
          translation 0 -0.03 0
          rotation 0 0 1 1.5708
          children [
            HingeJoint {
              device [
                RotationalMotor {
                  name "back wheel motor"
                }
              ]
              endPoint Solid {
                translation 0 0 -0.04
                rotation 1 0 0 1.5708
                children [
                  Shape {
                    appearance Appearance {
                      material Material {
                      }
                    }
                    geometry Cylinder {
                      height 0.01
                      radius 0.03
                    }
                  }
                ]
                name "LEFT_WHEEL"
              }
            }
            HingeJoint {
              device [
                RotationalMotor {
                  name "left wheel motor"
                }
              ]
              endPoint Solid {
                translation 0 -0.03 0.02
                rotation 1 0 0 -0.5236
                children [
                  Shape {
                    appearance Appearance {
                      material Material {
                      }
                    }
                    geometry Cylinder {
                      height 0.01
                      radius 0.03
                    }
                  }
                ]
                name "LEFT_WHEEL"
              }
            }
            HingeJoint {
              device [
                RotationalMotor {
                  name "right wheel motor"
                }
              ]
              endPoint Solid {
                translation 0 0.03 0.02
                rotation 1 0 0 0.5236
                children [
                  Shape {
                    appearance Appearance {
                      material Material {
                      }
                    }
                    geometry Cylinder {
                      height 0.01
                      radius 0.03
                    }
                  }
                ]
                name "LEFT_WHEEL"
              }
            }
          ]
        }
        DEF FRONT_CAM Camera {
          translation 0 0 0.05
          rotation 0 1 0 3.14159
          children [
            Shape {
              geometry Box {
                size 0.01 0.01 0.01
              }
            }
          ]
        }
        DEF BODY Shape {
          appearance Appearance {
            material Material {
              diffuseColor 1 0.5 0.5
              emissiveColor 0.5 0 0
            }
          }
          geometry Box {
            size 0.1 0.1 0.1
          }
        }
      ]
    }
  ]
  name "EyeBot"
}
