#VRML_SIM V8.5 utf8
WorldInfo {
  basicTimeStep 16
}
Viewpoint {
  orientation -0.99820079 0.014999622 -0.058053305 0.78099437
  position 0.081047338 0.884544 0.870867
}
Background {
  skyColor [
    0.4 0.7 1
  ]
}
DirectionalLight {
  ambientIntensity 1
  direction -0.33 -1 -0.5
  castShadows TRUE
}
Floor {
  size 1 1
}
DEF WALL_1 Solid {
  translation 0.5 0.05 0
  children [
    DEF WALL_SHAPE Shape {
      appearance Appearance {
        material Material {
          diffuseColor 0.12549 0.368627 0.729412
        }
      }
      geometry Box {
        size 0.02 0.1 0.98
      }
    }
  ]
  boundingObject USE WALL_SHAPE
}
DEF WALL_2 Solid {
  translation -0.5 0.05 0
  children [
    USE WALL_SHAPE
  ]
  boundingObject USE WALL_SHAPE
}
DEF WALL_3 Solid {
  translation 0 0.05 -0.5
  rotation 0 1 0 1.5708
  children [
    USE WALL_SHAPE
  ]
  boundingObject USE WALL_SHAPE
}
DEF WALL_4 Solid {
  translation 0 0.05 0.5
  rotation 0 1 0 1.5708
  children [
    USE WALL_SHAPE
  ]
  boundingObject USE WALL_SHAPE
}
Robot {
  translation 0 0.1 0
  children [
    DEF FRONT_CAM Camera {
      translation 0 0.02667 0.05715
      rotation 0 1 0 3.14159
      children [
        Shape {
          appearance Appearance {
            material Material {
              diffuseColor 0 0 0
            }
          }
          geometry Box {
            size 0.01 0.01 0.01
          }
        }
      ]
    }
    DEF WHEEL_TRANSFORM Transform {
      translation 0 -0.035 0
      rotation 0 0 1 1.5708
      children [
        HingeJoint {
          jointParameters HingeJointParameters {
            axis 0 1 -1
          }
          device [
            RotationalMotor {
              name "left wheel motor"
            }
          ]
          endPoint Solid {
            translation 0 -0.03 0.03
            rotation -1 0 0 0.78539969
            children [
              DEF LEFT_WHEEL Shape {
                appearance Appearance {
                  material Material {
                  }
                }
                geometry Cylinder {
                  height 0.01
                  radius 0.03
                }
              }
            ]
            name "LEFT_WHEEL"
            boundingObject USE LEFT_WHEEL
            physics Physics {
            }
          }
        }
        HingeJoint {
          jointParameters HingeJointParameters {
            axis 0 1 1
          }
          device [
            RotationalMotor {
              name "right wheel motor"
            }
          ]
          endPoint Solid {
            translation 0 0.03 0.03
            rotation 1 0 0 0.78539969
            children [
              DEF RIGHT_WHEEL Shape {
                appearance Appearance {
                  material Material {
                  }
                }
                geometry Cylinder {
                  height 0.01
                  radius 0.03
                }
              }
            ]
            name "RIGHT_WHEEL"
            boundingObject USE RIGHT_WHEEL
            physics Physics {
            }
          }
        }
        HingeJoint {
          jointParameters HingeJointParameters {
            axis 0 0 1
          }
          device [
            RotationalMotor {
              name "back wheel motor"
            }
          ]
          endPoint Solid {
            translation 0 0 -0.04
            rotation 1 0 0 1.5708
            children [
              DEF BACK_WHEEL Shape {
                appearance Appearance {
                  material Material {
                  }
                }
                geometry Cylinder {
                  height 0.01
                  radius 0.03
                }
              }
            ]
            name "BACK_WHEEL"
            boundingObject USE BACK_WHEEL
            physics Physics {
            }
          }
        }
      ]
    }
    DEF LEFT_SONAR DistanceSensor {
      translation 0.05715 0 0
      children [
        Shape {
          appearance Appearance {
            material Material {
              diffuseColor 0 0 0
            }
          }
          geometry Box {
            size 0.01 0.01 0.01
          }
        }
      ]
      name "left distance sensor"
      lookupTable [
        0 0 0
        1 1000 0
      ]
      type "sonar"
      numberOfRays 2
    }
    DEF RIGHT_SONAR DistanceSensor {
      translation -0.05715 0 0
      rotation 0 1 0 3.14159
      children [
        Shape {
          appearance Appearance {
            material Material {
              diffuseColor 0 0 0
            }
          }
          geometry Box {
            size 0.01 0.01 0.01
          }
        }
      ]
      name "right distance sensor"
      lookupTable [
        0 0 0
        1 1000 0
      ]
      type "sonar"
      numberOfRays 2
    }
    DEF FRONT_CONN Connector {
      translation 0 0 0.05715
      name "front connector"
      isLocked TRUE
      autoLock TRUE
    }
    DEF BACK_CONN Connector {
      translation 0 0 -0.05715
      name "back connector"
      isLocked TRUE
      autoLock TRUE
    }
    DEF LEFT_CONN Connector {
      translation 0.05715 0 0
      name "left connector"
      isLocked TRUE
      autoLock TRUE
    }
    DEF RIGHT_CONN Connector {
      translation -0.05715 0 0
      name "right connector"
      isLocked TRUE
      autoLock TRUE
    }
    DEF BODY Shape {
      appearance Appearance {
        material Material {
          diffuseColor 1 0.3 0.2
          emissiveColor 0.5 0 0
        }
      }
      geometry Box {
        size 0.1143 0.1143 0.1143
      }
    }
  ]
  name "EyeBot"
  boundingObject USE BODY
  physics Physics {
  }
  controller "eyebot_test"
}
